Traceback (most recent call last):
  File "C:\Users\adjeg\AppData\Roaming\Python\Python310\site-packages\jupyter_cache\executors\utils.py", line 58, in single_nb_execution
    executenb(
  File "C:\Python\Python310\lib\site-packages\nbclient\client.py", line 1269, in execute
    return NotebookClient(nb=nb, resources=resources, km=km, **kwargs).execute()
  File "C:\Python\Python310\lib\site-packages\nbclient\util.py", line 85, in wrapped
    return just_run(coro(*args, **kwargs))
  File "C:\Python\Python310\lib\site-packages\nbclient\util.py", line 60, in just_run
    return loop.run_until_complete(coro)
  File "C:\Python\Python310\lib\asyncio\base_events.py", line 646, in run_until_complete
    return future.result()
  File "C:\Python\Python310\lib\site-packages\nbclient\client.py", line 707, in async_execute
    await self.async_execute_cell(
  File "C:\Python\Python310\lib\site-packages\nbclient\client.py", line 1025, in async_execute_cell
    await self._check_raise_for_error(cell, cell_index, exec_reply)
  File "C:\Python\Python310\lib\site-packages\nbclient\client.py", line 919, in _check_raise_for_error
    raise CellExecutionError.from_cell_and_msg(cell, exec_reply_content)
nbclient.exceptions.CellExecutionError: An error occurred while executing the following cell:
------------------
from randomuser import RandomUser
import pandas as pd
------------------

[1;31m---------------------------------------------------------------------------[0m
[1;31mModuleNotFoundError[0m                       Traceback (most recent call last)
Cell [1;32mIn [53], line 1[0m
[1;32m----> 1[0m [38;5;28;01mfrom[39;00m [38;5;21;01mrandomuser[39;00m [38;5;28;01mimport[39;00m RandomUser
[0;32m      2[0m [38;5;28;01mimport[39;00m [38;5;21;01mpandas[39;00m [38;5;28;01mas[39;00m [38;5;21;01mpd[39;00m

[1;31mModuleNotFoundError[0m: No module named 'randomuser'
ModuleNotFoundError: No module named 'randomuser'

